Workbook

Sheet Dashboard
A1: Van Trip Reservations — Admin Dashboard
A3: =CONCATENATE("Covering ",TEXT(MIN(Data!D2:D231),"mmm d, yyyy")," to ",TEXT(MAX(Data!D2:D231),"mmm d, yyyy")," — ",COUNTA(Data!A2:A231)," total requests") -> Covering Sep 7, 2025 to Aug 28, 2026 — 230 total requests
B5: TOTAL REQUESTS | D5: APPROVED | F5: AVG TAT (hrs) | I5: SLA % | K5: PENDING NOW
B6: =Summary!B7 -> 230 | D6: =Summary!B3 -> 125 | F6: =Summary!B53 -> 86.4 | I6: =Summary!B58 -> 0.8 | K6: =Summary!B4 -> 34
A57: SLA Compliance
A58: TAT (turnaround time) is measured from submission to the first driver assignment (i.e. when a request is Approved). A trip is within SLA if that gap is 12 hours or less. If a driver is later reassigned, the first-assignment time still applies.
B61: SLA COMPLIANCE | D61: WITHIN SLA | F61: BREACHED SLA | I61: TRIPS ASSIGNED
B62: =Summary!B58 -> 0.8 | D62: =Summary!B56 -> 100 | F62: =Summary!B57 -> 25 | I62: =Summary!B55 -> 125

Sheet Data
A1: Reference | B1: Status | C1: Date Submitted (PHT) | D1: Start Date & Time | E1: End Time | F1: Requestor | G1: Location | H1: From | I1: To | J1: Purpose | K1: Details | L1: Van Type | M1: Driver | N1: Van | O1: Plate Number | P1: Vendor | Q1: Cost | R1: Updated By | S1: Last Updated (PHT) | T1: Month | U1: Weekday | V1: Lead Time (Days) | W1: Assigned | X1: TAT (Hrs) | Y1: Within SLA (<=12h) | Z1: Pending Age (Days)
A2: VR-2025-000002 | B2: Approved | C2: 45903.461 | D2: 45907.271 | E2: 0.70833333 | F2: Mateo, Angel | G2: Iloilo | H2: GLS Building | I2: Standby | J2: Others | K2: Generated dashboard seed trip. | L2: Standby Van | M2: Padilla, Marlon | N2: VAN-001 | O2: FAR 8931 | R2: Abanto, Norlyn | S2: 45903.673 | T2: =TEXT(D2,"mmm yyyy") -> Sep 2025 | U2: =TEXT(D2,"ddd") -> Sun | V2: =INT(D2)-INT(C2) -> 4 | W2: =IF(M2="","No","Yes") -> Yes | X2: =IF(AND(W2="Yes",S2<>""),ROUND((S2-C2)*24,1),"") -> 5.1 | Y2: =IF(X2="","N/A",IF(X2<=12,"Yes","No")) -> Yes | Z2: =IF(B2="Pending",TODAY()-INT(C2),"")
A3: VR-2025-000001 | B3: Approved | C3: 45903.408 | D3: 45907.333 | E3: 0.70833333 | F3: Cruz, Ivan | G3: Iloilo | H3: AGT Tower lobby | I3: Standby | J3: Others | K3: Generated dashboard seed trip. | L3: Standby Van | M3: Ocampo, Dennis | N3: VAN-004 | O3: NII 6324 | R3: Abanto, Norlyn | S3: 45903.826 | T3: =TEXT(D3,"mmm yyyy") -> Sep 2025 | U3: =TEXT(D3,"ddd") -> Sun | V3: =INT(D3)-INT(C3) -> 4 | W3: =IF(M3="","No","Yes") -> Yes | X3: =IF(AND(W3="Yes",S3<>""),ROUND((S3-C3)*24,1),"") -> 10 | Y3: =IF(X3="","N/A",IF(X3<=12,"Yes","No")) -> Yes | Z3: =IF(B3="Pending",TODAY()-INT(C3),"")
A4: VR-2025-000003 | B4: Approved | C4: 45903.49 | D4: 45907.542 | F4: Salcedo, Liza | G4: Iloilo | H4: GLS Building | I4: AGT Tower lobby | J4: IT-Related | K4: Generated dashboard seed trip. | L4: Pickup / Drop-Off | M4: Sarmiento, Joel | N4: VAN-002 | O4: FAR 7820 | R4: Abanto, Norlyn | S4: 45903.912 | T4: =TEXT(D4,"mmm yyyy") -> Sep 2025 | U4: =TEXT(D4,"ddd") -> Sun | V4: =INT(D4)-INT(C4) -> 4 | W4: =IF(M4="","No","Yes") -> Yes | X4: =IF(AND(W4="Yes",S4<>""),ROUND((S4-C4)*24,1),"") -> 10.1 | Y4: =IF(X4="","N/A",IF(X4<=12,"Yes","No")) -> Yes | Z4: =IF(B4="Pending",TODAY()-INT(C4),"")
A5: VR-2025-000004 | B5: Cancelled | C5: 45904.71 | D5: 45908.271 | F5: Cruz, Ivan | G5: Manila | H5: GLS Building | I5: Hotel | J5: IT-Related | K5: Generated dashboard seed trip. | L5: Pickup / Drop-Off | R5: Abanto, Norlyn | S5: 45905.001 | T5: =TEXT(D5,"mmm yyyy") -> Sep 2025 | U5: =TEXT(D5,"ddd") -> Mon | V5: =INT(D5)-INT(C5) -> 4 | W5: =IF(M5="","No","Yes") -> No | X5: =IF(AND(W5="Yes",S5<>""),ROUND((S5-C5)*24,1),"") | Y5: =IF(X5="","N/A",IF(X5<=12,"Yes","No")) -> N/A | Z5: =IF(B5="Pending",TODAY()-INT(C5),"")
A6: VR-2025-000005 | B6: Rejected | C6: 45905.544 | D6: 45909.271 | E6: 0.70833333 | F6: Cruz, Ivan | G6: Manila | H6: GLS Building | I6: Standby | J6: Others | K6: Generated dashboard seed trip. | L6: Standby Van | R6: Abanto, Norlyn | S6: 45905.82 | T6: =TEXT(D6,"mmm yyyy") -> Sep 2025 | U6: =TEXT(D6,"ddd") -> Tue | V6: =INT(D6)-INT(C6) -> 4 | W6: =IF(M6="","No","Yes") -> No | X6: =IF(AND(W6="Yes",S6<>""),ROUND((S6-C6)*24,1),"") | Y6: =IF(X6="","N/A",IF(X6<=12,"Yes","No")) -> N/A | Z6: =IF(B6="Pending",TODAY()-INT(C6),"")
A7: VR-2025-000006 | B7: Cancelled | C7: 45906.462 | D7: 45910.729 | F7: Cruz, Ivan | G7: Manila | H7: GLS Building | I7: AGT Tower lobby | J7: HR/TA Related | K7: Generated dashboard seed trip. | L7: Pickup / Drop-Off | R7: Abanto, Norlyn | S7: 45906.73 | T7: =TEXT(D7,"mmm yyyy") -> Sep 2025 | U7: =TEXT(D7,"ddd") -> Wed | V7: =INT(D7)-INT(C7) -> 4 | W7: =IF(M7="","No","Yes") -> No | X7: =IF(AND(W7="Yes",S7<>""),ROUND((S7-C7)*24,1),"") | Y7: =IF(X7="","N/A",IF(X7<=12,"Yes","No")) -> N/A | Z7: =IF(B7="Pending",TODAY()-INT(C7),"")
A8: VR-2025-000007 | B8: Cancelled | C8: 45908.454 | D8: 45912.542 | F8: Reyes, Kaye | G8: Manila | H8: GLS Building | I8: AGT Tower lobby | J8: Others | K8: Generated dashboard seed trip. | L8: Pickup / Drop-Off | R8: Abanto, Norlyn | S8: 45908.753 | T8: =TEXT(D8,"mmm yyyy") -> Sep 2025 | U8: =TEXT(D8,"ddd") -> Fri | V8: =INT(D8)-INT(C8) -> 4 | W8: =IF(M8="","No","Yes") -> No | X8: =IF(AND(W8="Yes",S8<>""),ROUND((S8-C8)*24,1),"") | Y8: =IF(X8="","N/A",IF(X8<=12,"Yes","No")) -> N/A | Z8: =IF(B8="Pending",TODAY()-INT(C8),"")
A9: VR-2025-000008 | B9: Approved | C9: 45909.39 | D9: 45913.333 | F9: Salcedo, Liza | G9: Iloilo | H9: GLS Building | I9: Hotel | J9: IT-Related | K9: Generated dashboard seed trip. | L9: Pickup / Drop-Off | M9: Padilla, Marlon | N9: VAN-002 | O9: FAR 7820 | R9: Arielle Jimera | S9: 46274.648 | T9: =TEXT(D9,"mmm yyyy") -> Sep 2025 | U9: =TEXT(D9,"ddd") -> Sat | V9: =INT(D9)-INT(C9) -> 4 | W9: =IF(M9="","No","Yes") -> Yes | X9: =IF(AND(W9="Yes",S9<>""),ROUND((S9-C9)*24,1),"") -> 8766.2 | Y9: =IF(X9="","N/A",IF(X9<=12,"Yes","No")) -> No | Z9: =IF(B9="Pending",TODAY()-INT(C9),"")
A10: VR-2025-000009 | B10: Approved | C10: 45910.596 | D10: 45914.729 | E10: 0.041666667 | F10: Reyes, Kaye | G10: Iloilo | H10: GLS Building | I10: Standby | J10: Others | K10: Generated dashboard seed trip. | L10: Standby Van | M10: Sarmiento, Joel | N10: VAN-002 | O10: FAR 7820 | R10: Abanto, Norlyn | S10: 45910.785 | T10: =TEXT(D10,"mmm yyyy") -> Sep 2025 | U10: =TEXT(D10,"ddd") -> Sun | V10: =INT(D10)-INT(C10) -> 4 | W10: =IF(M10="","No","Yes") -> Yes | X10: =IF(AND(W10="Yes",S10<>""),ROUND((S10-C10)*24,1),"") -> 4.5 | Y10: =IF(X10="","N/A",IF(X10<=12,"Yes","No")) -> Yes | Z10: =IF(B10="Pending",TODAY()-INT(C10),"")
A11: VR-2025-000010 | B11: Approved | C11: 45917.606 | D11: 45921.271 | F11: Reyes, Kaye | G11: Manila | H11: AGT Tower lobby | I11: Airport | J11: IT-Related | K11: Generated dashboard seed trip. | L11: Pickup / Drop-Off | M11: Padilla, Marlon | N11: VAN-003 | O11: NHU 8001 | R11: Abanto, Norlyn | S11: 45918.238 | T11: =TEXT(D11,"mmm yyyy") -> Sep 2025 | U11: =TEXT(D11,"ddd") -> Sun | V11: =INT(D11)-INT(C11) -> 4 | W11: =IF(M11="","No","Yes") -> Yes | X11: =IF(AND(W11="Yes",S11<>""),ROUND((S11-C11)*24,1),"") -> 15.2 | Y11: =IF(X11="","N/A",IF(X11<=12,"Yes","No")) -> No | Z11: =IF(B11="Pending",TODAY()-INT(C11),"")
A12: VR-2025-000011 | B12: Approved | C12: 45918.595 | D12: 45922.271 | E12: 0.70833333 | F12: Reyes, Kaye | G12: Iloilo | H12: AGT Tower lobby | I12: Standby | J12: Others | K12: Generated dashboard seed trip. | L12: Standby Van | M12: Ocampo, Dennis | N12: VAN-001 | O12: FAR 8931 | R12: Abanto, Norlyn | S12: 45919.037 | T12: =TEXT(D12,"mmm yyyy") -> Sep 2025 | U12: =TEXT(D12,"ddd") -> Mon | V12: =INT(D12)-INT(C12) -> 4 | W12: =IF(M12="","No","Yes") -> Yes | X12: =IF(AND(W12="Yes",S12<>""),ROUND((S12-C12)*24,1),"") -> 10.6 | Y12: =IF(X12="","N/A",IF(X12<=12,"Yes","No")) -> Yes | Z12: =IF(B12="Pending",TODAY()-INT(C12),"")
A13: VR-2025-000012 | B13: Pending | C13: 45919.383 | D13: 45923.271 | F13: Mateo, Angel | G13: Manila | H13: AGT Tower lobby | I13: Airport | J13: Others | K13: Generated dashboard seed trip. | L13: Pickup / Drop-Off | T13: =TEXT(D13,"mmm yyyy") -> Sep 2025 | U13: =TEXT(D13,"ddd") -> Tue | V13: =INT(D13)-INT(C13) -> 4 | W13: =IF(M13="","No","Yes") -> No | X13: =IF(AND(W13="Yes",S13<>""),ROUND((S13-C13)*24,1),"") | Y13: =IF(X13="","N/A",IF(X13<=12,"Yes","No")) -> N/A | Z13: =IF(B13="Pending",TODAY()-INT(C13),"") -> 355
A14: VR-2025-000013 | B14: Approved | C14: 45919.398 | D14: 45923.292 | E14: 0.70833333 | F14: Reyes, Kaye | G14: Iloilo | H14: AGT Tower lobby | I14: Standby | J14: Others | K14: Generated dashboard seed trip. | L14: Standby Van | M14: Ocampo, Dennis | N14: VAN-004 | O14: NII 6324 | R14: Abanto, Norlyn | S14: 45919.875 | T14: =TEXT(D14,"mmm yyyy") -> Sep 2025 | U14: =TEXT(D14,"ddd") -> Tue | V14: =INT(D14)-INT(C14) -> 4 | W14: =IF(M14="","No","Yes") -> Yes | X14: =IF(AND(W14="Yes",S14<>""),ROUND((S14-C14)*24,1),"") -> 11.5 | Y14: =IF(X14="","N/A",IF(X14<=12,"Yes","No")) -> Yes | Z14: =IF(B14="Pending",TODAY()-INT(C14),"")
A15: VR-2025-000014 | B15: Approved | C15: 45919.405 | D15: 45923.292 | E15: 0.70833333 | F15: Cruz, Ivan | G15: Iloilo | H15: GLS Building | I15: Standby | J15: Others | K15: Generated dashboard seed trip. | L15: Standby Van | M15: Padilla, Marlon | N15: VAN-001 | O15: FAR 8931 | R15: Abanto, Norlyn | S15: 45919.709 | T15: =TEXT(D15,"mmm yyyy") -> Sep 2025 | U15: =TEXT(D15,"ddd") -> Tue | V15: =INT(D15)-INT(C15) -> 4 | W15: =IF(M15="","No","Yes") -> Yes | X15: =IF(AND(W15="Yes",S15<>""),ROUND((S15-C15)*24,1),"") -> 7.3 | Y15: =IF(X15="","N/A",IF(X15<=12,"Yes","No")) -> Yes | Z15: =IF(B15="Pending",TODAY()-INT(C15),"")
A16: VR-2025-000016 | B16: Approved | C16: 45921.516 | D16: 45925.271 | E16: 0.70833333 | F16: Cruz, Ivan | G16: Manila | H16: GLS Building | I16: Standby | J16: Others | K16: Generated dashboard seed trip. | L16: Standby Van | M16: Sarmiento, Joel | N16: VAN-002 | O16: FAR 7820 | R16: Abanto, Norlyn | S16: 45921.724 | T16: =TEXT(D16,"mmm yyyy") -> Sep 2025 | U16: =TEXT(D16,"ddd") -> Thu | V16: =INT(D16)-INT(C16) -> 4 | W16: =IF(M16="","No","Yes") -> Yes | X16: =IF(AND(W16="Yes",S16<>""),ROUND((S16-C16)*24,1),"") -> 5 | Y16: =IF(X16="","N/A",IF(X16<=12,"Yes","No")) -> Yes | Z16: =IF(B16="Pending",TODAY()-INT(C16),"")
A17: VR-2025-000015 | B17: Approved | C17: 45921.426 | D17: 45925.292 | F17: Jimera, Arielle | G17: Manila | H17: GLS Building | I17: AGT Tower lobby | J17: IT-Related | K17: Generated dashboard seed trip. | L17: Pickup / Drop-Off | M17: Ocampo, Dennis | N17: VAN-003 | O17: NHU 8001 | R17: Abanto, Norlyn | S17: 45921.471 | T17: =TEXT(D17,"mmm yyyy") -> Sep 2025 | U17: =TEXT(D17,"ddd") -> Thu | V17: =INT(D17)-INT(C17) -> 4 | W17: =IF(M17="","No","Yes") -> Yes | X17: =IF(AND(W17="Yes",S17<>""),ROUND((S17-C17)*24,1),"") -> 1.1 | Y17: =IF(X17="","N/A",IF(X17<=12,"Yes","No")) -> Yes | Z17: =IF(B17="Pending",TODAY()-INT(C17),"")
A18: VR-2025-000018 | B18: Approved | C18: 45922.668 | D18: 45926.542 | E18: 0.70833333 | F18: Cruz, Ivan | G18: Iloilo | H18: GLS Building | I18: Standby | J18: Others | K18: Generated dashboard seed trip. | L18: Standby Van | M18: Villanueva, Rey | N18: VAN-004 | O18: NII 6324 | R18: Abanto, Norlyn | S18: 45922.833 | T18: =TEXT(D18,"mmm yyyy") -> Sep 2025 | U18: =TEXT(D18,"ddd") -> Fri | V18: =INT(D18)-INT(C18) -> 4 | W18: =IF(M18="","No","Yes") -> Yes | X18: =IF(AND(W18="Yes",S18<>""),ROUND((S18-C18)*24,1),"") -> 4 | Y18: =IF(X18="","N/A",IF(X18<=12,"Yes","No")) -> Yes | Z18: =IF(B18="Pending",TODAY()-INT(C18),"")
A19: VR-2025-000017 | B19: Pending | C19: 45922.617 | D19: 45926.542 | E19: 0.70833333 | F19: Jimera, Arielle | G19: Manila | H19: GLS Building | I19: Standby | J19: Others | K19: Generated dashboard seed trip. | L19: Standby Van | T19: =TEXT(D19,"mmm yyyy") -> Sep 2025 | U19: =TEXT(D19,"ddd") -> Fri | V19: =INT(D19)-INT(C19) -> 4 | W19: =IF(M19="","No","Yes") -> No | X19: =IF(AND(W19="Yes",S19<>""),ROUND((S19-C19)*24,1),"") | Y19: =IF(X19="","N/A",IF(X19<=12,"Yes","No")) -> N/A | Z19: =IF(B19="Pending",TODAY()-INT(C19),"") -> 352
A20: VR-2025-000021 | B20: Approved | C20: 45926.479 | D20: 45928.292 | F20: Salcedo, Liza | G20: Manila | H20: GLS Building | I20: Hotel | J20: IT-Related | K20: Generated dashboard seed trip. | L20: Pickup / Drop-Off | M20: Villanueva, Rey | N20: VAN-003 | O20: NHU 8001 | R20: Abanto, Norlyn | S20: 45926.683 | T20: =TEXT(D20,"mmm yyyy") -> Sep 2025 | U20: =TEXT(D20,"ddd") -> Sun | V20: =INT(D20)-INT(C20) -> 2 | W20: =IF(M20="","No","Yes") -> Yes | X20: =IF(AND(W20="Yes",S20<>""),ROUND((S20-C20)*24,1),"") -> 4.9 | Y20: =IF(X20="","N/A",IF(X20<=12,"Yes","No")) -> Yes | Z20: =IF(B20="Pending",TODAY()-INT(C20),"")
A21: VR-2025-000020 | B21: Approved | C21: 45924.732 | D21: 45928.333 | E21: 0.70833333 | F21: Jimera, Arielle | G21: Manila | H21: GLS Building | I21: Standby | J21: Others | K21: Generated dashboard seed trip. | L21: Standby Van | M21: Ocampo, Dennis | N21: VAN-001 | O21: FAR 8931 | R21: Abanto, Norlyn | S21: 45924.884 | T21: =TEXT(D21,"mmm yyyy") -> Sep 2025 | U21: =TEXT(D21,"ddd") -> Sun | V21: =INT(D21)-INT(C21) -> 4 | W21: =IF(M21="","No","Yes") -> Yes | X21: =IF(AND(W21="Yes",S21<>""),ROUND((S21-C21)*24,1),"") -> 3.7 | Y21: =IF(X21="","N/A",IF(X21<=12,"Yes","No")) -> Yes | Z21: =IF(B21="Pending",TODAY()-INT(C21),"")
A22: VR-2025-000022 | B22: Cancelled | C22: 45926.644 | D22: 45928.333 | E22: 0.70833333 | F22: Jimera, Arielle | G22: Manila | H22: AGT Tower lobby | I22: Standby | J22: Others | K22: Generated dashboard seed trip. | L22: Standby Van | R22: Abanto, Norlyn | S22: 45927.112 | T22: =TEXT(D22,"mmm yyyy") -> Sep 2025 | U22: =TEXT(D22,"ddd") -> Sun | V22: =INT(D22)-INT(C22) -> 2 | W22: =IF(M22="","No","Yes") -> No | X22: =IF(AND(W22="Yes",S22<>""),ROUND((S22-C22)*24,1),"") | Y22: =IF(X22="","N/A",IF(X22<=12,"Yes","No")) -> N/A | Z22: =IF(B22="Pending",TODAY()-INT(C22),"")
A23: VR-2025-000019 | B23: Approved | C23: 45924.512 | D23: 45928.729 | F23: Dizon, Marco | G23: Manila | H23: AGT Tower lobby | I23: GLS Building | J23: IT-Related | K23: Generated dashboard seed trip. | L23: Pickup / Drop-Off | M23: Padilla, Marlon | N23: VAN-003 | O23: NHU 8001 | R23: Abanto, Norlyn | S23: 45924.845 | T23: =TEXT(D23,"mmm yyyy") -> Sep 2025 | U23: =TEXT(D23,"ddd") -> Sun | V23: =INT(D23)-INT(C23) -> 4 | W23: =IF(M23="","No","Yes") -> Yes | X23: =IF(AND(W23="Yes",S23<>""),ROUND((S23-C23)*24,1),"") -> 8 | Y23: =IF(X23="","N/A",IF(X23<=12,"Yes","No")) -> Yes | Z23: =IF(B23="Pending",TODAY()-INT(C23),"")
A24: VR-2025-000023 | B24: Approved | C24: 45931.616 | D24: 45935.729 | E24: 0.041666667 | F24: Reyes, Kaye | G24: Manila | H24: GLS Building | I24: Standby | J24: Others | K24: Generated dashboard seed trip. | L24: Standby Van | M24: Villanueva, Rey | N24: VAN-001 | O24: FAR 8931 | R24: Abanto, Norlyn | S24: 45931.993 | T24: =TEXT(D24,"mmm yyyy") -> Oct 2025 | U24: =TEXT(D24,"ddd") -> Sun | V24: =INT(D24)-INT(C24) -> 4 | W24: =IF(M24="","No","Yes") -> Yes | X24: =IF(AND(W24="Yes",S24<>""),ROUND((S24-C24)*24,1),"") -> 9.1 | Y24: =IF(X24="","N/A",IF(X24<=12,"Yes","No")) -> Yes | Z24: =IF(B24="Pending",TODAY()-INT(C24),"")
A25: VR-2025-000024 | B25: Approved | C25: 45932.731 | D25: 45936.542 | F25: Jimera, Arielle | G25: Manila | H25: AGT Tower lobby | I25: GLS Building | J25: HR/TA Related | K25: Generated dashboard seed trip. | L25: Pickup / Drop-Off | M25: Ocampo, Dennis | N25: VAN-003 | O25: NHU 8001 | R25: Abanto, Norlyn | S25: 45933.088 | T25: =TEXT(D25,"mmm yyyy") -> Oct 2025 | U25: =TEXT(D25,"ddd") -> Mon | V25: =INT(D25)-INT(C25) -> 4 | W25: =IF(M25="","No","Yes") -> Yes | X25: =IF(AND(W25="Yes",S25<>""),ROUND((S25-C25)*24,1),"") -> 8.6 | Y25: =IF(X25="","N/A",IF(X25<=12,"Yes","No")) -> Yes | Z25: =IF(B25="Pending",TODAY()-INT(C25),"")
A26: VR-2025-000025 | B26: Approved | C26: 45933.458 | D26: 45937.542 | F26: Mateo, Angel | G26: Manila | H26: GLS Building | I26: Hotel | J26: HR/TA Related | K26: Generated dashboard seed trip. | L26: Pickup / Drop-Off | M26: Ocampo, Dennis | N26: VAN-004 | O26: NII 6324 | R26: Abanto, Norlyn | S26: 45933.853 | T26: =TEXT(D26,"mmm yyyy") -> Oct 2025 | U26: =TEXT(D26,"ddd") -> Tue | V26: =INT(D26)-INT(C26) -> 4 | W26: =IF(M26="","No","Yes") -> Yes | X26: =IF(AND(W26="Yes",S26<>""),ROUND((S26-C26)*24,1),"") -> 9.5 | Y26: =IF(X26="","N/A",IF(X26<=12,"Yes","No")) -> Yes | Z26: =IF(B26="Pending",TODAY()-INT(C26),"")
A27: VR-2025-000026 | B27: Approved | C27: 45935.608 | D27: 45939.333 | F27: Cruz, Ivan | G27: Manila | H27: AGT Tower lobby | I27: GLS Building | J27: IT-Related | K27: Generated dashboard seed trip. | L27: Pickup / Drop-Off | M27: Villanueva, Rey | N27: VAN-003 | O27: NHU 8001 | R27: Abanto, Norlyn | S27: 45936.083 | T27: =TEXT(D27,"mmm yyyy") -> Oct 2025 | U27: =TEXT(D27,"ddd") -> Thu | V27: =INT(D27)-INT(C27) -> 4 | W27: =IF(M27="","No","Yes") -> Yes | X27: =IF(AND(W27="Yes",S27<>""),ROUND((S27-C27)*24,1),"") -> 11.4 | Y27: =IF(X27="","N/A",IF(X27<=12,"Yes","No")) -> Yes | Z27: =IF(B27="Pending",TODAY()-INT(C27),"")
A28: VR-2025-000027 | B28: Rejected | C28: 45935.643 | D28: 45939.333 | F28: Cruz, Ivan | G28: Iloilo | H28: AGT Tower lobby | I28: GLS Building | J28: HR/TA Related | K28: Generated dashboard seed trip. | L28: Pickup / Drop-Off | R28: Abanto, Norlyn | S28: 45935.797 | T28: =TEXT(D28,"mmm yyyy") -> Oct 2025 | U28: =TEXT(D28,"ddd") -> Thu | V28: =INT(D28)-INT(C28) -> 4 | W28: =IF(M28="","No","Yes") -> No | X28: =IF(AND(W28="Yes",S28<>""),ROUND((S28-C28)*24,1),"") | Y28: =IF(X28="","N/A",IF(X28<=12,"Yes","No")) -> N/A | Z28: =IF(B28="Pending",TODAY()-INT(C28),"")
A29: VR-2025-000028 | B29: Rejected | C29: 45938.415 | D29: 45942.542 | F29: Mateo, Angel | G29: Iloilo | H29: AGT Tower lobby | I29: Airport | J29: HR/TA Related | K29: Generated dashboard seed trip. | L29: Pickup / Drop-Off | R29: Abanto, Norlyn | S29: 45938.726 | T29: =TEXT(D29,"mmm yyyy") -> Oct 2025 | U29: =TEXT(D29,"ddd") -> Sun | V29: =INT(D29)-INT(C29) -> 4 | W29: =IF(M29="","No","Yes") -> No | X29: =IF(AND(W29="Yes",S29<>""),ROUND((S29-C29)*24,1),"") | Y29: =IF(X29="","N/A",IF(X29<=12,"Yes","No")) -> N/A | Z29: =IF(B29="Pending",TODAY()-INT(C29),"")
A30: VR-2025-000029 | B30: Approved | C30: 45940.464 | D30: 45944.292 | E30: 0.70833333 | F30: Dizon, Marco | G30: Iloilo | H30: GLS Building | I30: Standby | J30: Others | K30: Generated dashboard seed trip. | L30: Standby Van | M30: Padilla, Marlon | N30: VAN-001 | O30: FAR 8931 | R30: Abanto, Norlyn | S30: 45941.588 | T30: =TEXT(D30,"mmm yyyy") -> Oct 2025 | U30: =TEXT(D30,"ddd") -> Tue | V30: =INT(D30)-INT(C30) -> 4 | W30: =IF(M30="","No","Yes") -> Yes | X30: =IF(AND(W30="Yes",S30<>""),ROUND((S30-C30)*24,1),"") -> 27 | Y30: =IF(X30="","N/A",IF(X30<=12,"Yes","No")) -> No | Z30: =IF(B30="Pending",TODAY()-INT(C30),"")
A31: VR-2025-000030 | B31: Cancelled | C31: 45940.622 | D31: 45944.542 | F31: Mateo, Angel | G31: Manila | H31: AGT Tower lobby | I31: Airport | J31: HR/TA Related | K31: Generated dashboard seed trip. | L31: Pickup / Drop-Off | R31: Abanto, Norlyn | S31: 45941.207 | T31: =TEXT(D31,"mmm yyyy") -> Oct 2025 | U31: =TEXT(D31,"ddd") -> Tue | V31: =INT(D31)-INT(C31) -> 4 | W31: =IF(M31="","No","Yes") -> No | X31: =IF(AND(W31="Yes",S31<>""),ROUND((S31-C31)*24,1),"") | Y31: =IF(X31="","N/A",IF(X31<=12,"Yes","No")) -> N/A | Z31: =IF(B31="Pending",TODAY()-INT(C31),"")
A32: VR-2025-000031 | B32: Approved | C32: 45946.547 | D32: 45950.271 | F32: Mateo, Angel | G32: Manila | H32: GLS Building | I32: Hotel | J32: Others | K32: Generated dashboard seed trip. | L32: Pickup / Drop-Off | M32: Padilla, Marlon | N32: VAN-002 | O32: FAR 7820 | R32: Abanto, Norlyn | S32: 45946.608 | T32: =TEXT(D32,"mmm yyyy") -> Oct 2025 | U32: =TEXT(D32,"ddd") -> Mon | V32: =INT(D32)-INT(C32) -> 4 | W32: =IF(M32="","No","Yes") -> Yes | X32: =IF(AND(W32="Yes",S32<>""),ROUND((S32-C32)*24,1),"") -> 1.5 | Y32: =IF(X32="","N/A",IF(X32<=12,"Yes","No")) -> Yes | Z32: =IF(B32="Pending",TODAY()-INT(C32),"")
A33: VR-2025-000032 | B33: Approved | C33: 45947.399 | D33: 45951.542 | F33: Reyes, Kaye | G33: Iloilo | H33: GLS Building | I33: AGT Tower lobby | J33: HR/TA Related | K33: Generated dashboard seed trip. | L33: Pickup / Drop-Off | M33: Villanueva, Rey | N33: VAN-001 | O33: FAR 8931 | R33: Abanto, Norlyn | S33: 45947.678 | T33: =TEXT(D33,"mmm yyyy") -> Oct 2025 | U33: =TEXT(D33,"ddd") -> Tue | V33: =INT(D33)-INT(C33) -> 4 | W33: =IF(M33="","No","Yes") -> Yes | X33: =IF(AND(W33="Yes",S33<>""),ROUND((S33-C33)*24,1),"") -> 6.7 | Y33: =IF(X33="","N/A",IF(X33<=12,"Yes","No")) -> Yes | Z33: =IF(B33="Pending",TODAY()-INT(C33),"")
A34: VR-2025-000033 | B34: Approved | C34: 45948.434 | D34: 45952.542 | F34: Salcedo, Liza | G34: Manila | H34: AGT Tower lobby | I34: Airport | J34: Others | K34: Generated dashboard seed trip. | L34: Pickup / Drop-Off | M34: Sarmiento, Joel | N34: VAN-003 | O34: NHU 8001 | R34: Abanto, Norlyn | S34: 45949.592 | T34: =TEXT(D34,"mmm yyyy") -> Oct 2025 | U34: =TEXT(D34,"ddd") -> Wed | V34: =INT(D34)-INT(C34) -> 4 | W34: =IF(M34="","No","Yes") -> Yes | X34: =IF(AND(W34="Yes",S34<>""),ROUND((S34-C34)*24,1),"") -> 27.8 | Y34: =IF(X34="","N/A",IF(X34<=12,"Yes","No")) -> No | Z34: =IF(B34="Pending",TODAY()-INT(C34),"")
A35: VR-2025-000034 | B35: Cancelled | C35: 45949.645 | D35: 45953.271 | E35: 0.70833333 | F35: Jimera, Arielle | G35: Manila | H35: AGT Tower lobby | I35: Standby | J35: Others | K35: Generated dashboard seed trip. | L35: Standby Van | R35: Abanto, Norlyn | S35: 45949.85 | T35: =TEXT(D35,"mmm yyyy") -> Oct 2025 | U35: =TEXT(D35,"ddd") -> Thu | V35: =INT(D35)-INT(C35) -> 4 | W35: =IF(M35="","No","Yes") -> No | X35: =IF(AND(W35="Yes",S35<>""),ROUND((S35-C35)*24,1),"") | Y35: =IF(X35="","N/A",IF(X35<=12,"Yes","No")) -> N/A | Z35: =IF(B35="Pending",TODAY()-INT(C35),"")
A36: VR-2025-000035 | B36: Approved | C36: 45949.731 | D36: 45953.333 | F36: Salcedo, Liza | G36: Manila | H36: AGT Tower lobby | I36: GLS Building | J36: IT-Related | K36: Generated dashboard seed trip. | L36: Pickup / Drop-Off | M36: Ocampo, Dennis | N36: VAN-004 | O36: NII 6324 | R36: Abanto, Norlyn | S36: 45949.828 | T36: =TEXT(D36,"mmm yyyy") -> Oct 2025 | U36: =TEXT(D36,"ddd") -> Thu | V36: =INT(D36)-INT(C36) -> 4 | W36: =IF(M36="","No","Yes") -> Yes | X36: =IF(AND(W36="Yes",S36<>""),ROUND((S36-C36)*24,1),"") -> 2.3 | Y36: =IF(X36="","N/A",IF(X36<=12,"Yes","No")) -> Yes | Z36: =IF(B36="Pending",TODAY()-INT(C36),"")
A37: VR-2025-000036 | B37: Approved | C37: 45950.499 | D37: 45954.729 | E37: 0.041666667 | F37: Jimera, Arielle | G37: Iloilo | H37: AGT Tower lobby | I37: Standby | J37: Others | K37: Generated dashboard seed trip. | L37: Standby Van | M37: Sarmiento, Joel | N37: VAN-003 | O37: NHU 8001 | R37: Abanto, Norlyn | S37: 45950.667 | T37: =TEXT(D37,"mmm yyyy") -> Oct 2025 | U37: =TEXT(D37,"ddd") -> Fri | V37: =INT(D37)-INT(C37) -> 4 | W37: =IF(M37="","No","Yes") -> Yes | X37: =IF(AND(W37="Yes",S37<>""),ROUND((S37-C37)*24,1),"") -> 4 | Y37: =IF(X37="","N/A",IF(X37<=12,"Yes","No")) -> Yes | Z37: =IF(B37="Pending",TODAY()-INT(C37),"")
A38: VR-2025-000037 | B38: Approved | C38: 45951.659 | D38: 45955.542 | F38: Cruz, Ivan | G38: Manila | H38: GLS Building | I38: AGT Tower lobby | J38: HR/TA Related | K38: Generated dashboard seed trip. | L38: Pickup / Drop-Off | M38: Padilla, Marlon | N38: VAN-003 | O38: NHU 8001 | R38: Abanto, Norlyn | S38: 45951.801 | T38: =TEXT(D38,"mmm yyyy") -> Oct 2025 | U38: =TEXT(D38,"ddd") -> Sat | V38: =INT(D38)-INT(C38) -> 4 | W38: =IF(M38="","No","Yes") -> Yes | X38: =IF(AND(W38="Yes",S38<>""),ROUND((S38-C38)*24,1),"") -> 3.4 | Y38: =IF(X38="","N/A",IF(X38<=12,"Yes","No")) -> Yes | Z38: =IF(B38="Pending",TODAY()-INT(C38),"")
A39: VR-2025-000038 | B39: Approved | C39: 45952.662 | D39: 45956.542 | E39: 0.70833333 | F39: Cruz, Ivan | G39: Iloilo | H39: AGT Tower lobby | I39: Standby | J39: Others | K39: Generated dashboard seed trip. | L39: Standby Van | M39: Padilla, Marlon | N39: VAN-003 | O39: NHU 8001 | R39: Abanto, Norlyn | S39: 45952.847 | T39: =TEXT(D39,"mmm yyyy") -> Oct 2025 | U39: =TEXT(D39,"ddd") -> Sun | V39: =INT(D39)-INT(C39) -> 4 | W39: =IF(M39="","No","Yes") -> Yes | X39: =IF(AND(W39="Yes",S39<>""),ROUND((S39-C39)*24,1),"") -> 4.4 | Y39: =IF(X39="","N/A",IF(X39<=12,"Yes","No")) -> Yes | Z39: =IF(B39="Pending",TODAY()-INT(C39),"")
A40: VR-2025-000040 | B40: Approved | C40: 45956.472 | D40: 45958.292 | F40: Dizon, Marco | G40: Manila | H40: AGT Tower lobby | I40: Airport | J40: Others | K40: Generated dashboard seed trip. | L40: Pickup / Drop-Off | M40: Villanueva, Rey | N40: VAN-001 | O40: FAR 8931 | R40: Abanto, Norlyn | S40: 45956.722 | T40: =TEXT(D40,"mmm yyyy") -> Oct 2025 | U40: =TEXT(D40,"ddd") -> Tue | V40: =INT(D40)-INT(C40) -> 2 | W40: =IF(M40="","No","Yes") -> Yes | X40: =IF(AND(W40="Yes",S40<>""),ROUND((S40-C40)*24,1),"") -> 6 | Y40: =IF(X40="","N/A",IF(X40<=12,"Yes","No")) -> Yes | Z40: =IF(B40="Pending",TODAY()-INT(C40),"")
...

Sheet Summary
A1: Status Breakdown
A2: Status | B2: Count | C2: % of Total
A3: Approved | B3: =COUNTIF(Data!$B$2:$B$231,A3) -> 125 | C3: =B3/SUM($B$3:$B$6) -> 0.54347826
A4: Pending | B4: =COUNTIF(Data!$B$2:$B$231,A4) -> 34 | C4: =B4/SUM($B$3:$B$6) -> 0.14782609
A5: Rejected | B5: =COUNTIF(Data!$B$2:$B$231,A5) -> 31 | C5: =B5/SUM($B$3:$B$6) -> 0.13478261
A6: Cancelled | B6: =COUNTIF(Data!$B$2:$B$231,A6) -> 40 | C6: =B6/SUM($B$3:$B$6) -> 0.17391304
A7: Total | B7: =SUM(B3:B6) -> 230
A9: Monthly Trend
A10: Month | B10: Total | C10: Approved | D10: Pending | E10: Rejected | F10: Cancelled
A11: Sep 2025 | B11: =COUNTIF(Data!$T$2:$T$231,A11) -> 22 | C11: =COUNTIFS(Data!$T$2:$T$231,A11,Data!$B$2:$B$231,"Approved") -> 15 | D11: =COUNTIFS(Data!$T$2:$T$231,A11,Data!$B$2:$B$231,"Pending") -> 2 | E11: =COUNTIFS(Data!$T$2:$T$231,A11,Data!$B$2:$B$231,"Rejected") -> 1 | F11: =COUNTIFS(Data!$T$2:$T$231,A11,Data!$B$2:$B$231,"Cancelled") -> 4
A12: Oct 2025 | B12: =COUNTIF(Data!$T$2:$T$231,A12) -> 19 | C12: =COUNTIFS(Data!$T$2:$T$231,A12,Data!$B$2:$B$231,"Approved") -> 13 | D12: =COUNTIFS(Data!$T$2:$T$231,A12,Data!$B$2:$B$231,"Pending") -> 1 | E12: =COUNTIFS(Data!$T$2:$T$231,A12,Data!$B$2:$B$231,"Rejected") -> 3 | F12: =COUNTIFS(Data!$T$2:$T$231,A12,Data!$B$2:$B$231,"Cancelled") -> 2
A13: Nov 2025 | B13: =COUNTIF(Data!$T$2:$T$231,A13) -> 16 | C13: =COUNTIFS(Data!$T$2:$T$231,A13,Data!$B$2:$B$231,"Approved") -> 9 | D13: =COUNTIFS(Data!$T$2:$T$231,A13,Data!$B$2:$B$231,"Pending") -> 0 | E13: =COUNTIFS(Data!$T$2:$T$231,A13,Data!$B$2:$B$231,"Rejected") -> 2 | F13: =COUNTIFS(Data!$T$2:$T$231,A13,Data!$B$2:$B$231,"Cancelled") -> 5
A14: Dec 2025 | B14: =COUNTIF(Data!$T$2:$T$231,A14) -> 14 | C14: =COUNTIFS(Data!$T$2:$T$231,A14,Data!$B$2:$B$231,"Approved") -> 4 | D14: =COUNTIFS(Data!$T$2:$T$231,A14,Data!$B$2:$B$231,"Pending") -> 3 | E14: =COUNTIFS(Data!$T$2:$T$231,A14,Data!$B$2:$B$231,"Rejected") -> 5 | F14: =COUNTIFS(Data!$T$2:$T$231,A14,Data!$B$2:$B$231,"Cancelled") -> 2
A15: Jan 2026 | B15: =COUNTIF(Data!$T$2:$T$231,A15) -> 24 | C15: =COUNTIFS(Data!$T$2:$T$231,A15,Data!$B$2:$B$231,"Approved") -> 15 | D15: =COUNTIFS(Data!$T$2:$T$231,A15,Data!$B$2:$B$231,"Pending") -> 4 | E15: =COUNTIFS(Data!$T$2:$T$231,A15,Data!$B$2:$B$231,"Rejected") -> 1 | F15: =COUNTIFS(Data!$T$2:$T$231,A15,Data!$B$2:$B$231,"Cancelled") -> 4
A16: Feb 2026 | B16: =COUNTIF(Data!$T$2:$T$231,A16) -> 20 | C16: =COUNTIFS(Data!$T$2:$T$231,A16,Data!$B$2:$B$231,"Approved") -> 12 | D16: =COUNTIFS(Data!$T$2:$T$231,A16,Data!$B$2:$B$231,"Pending") -> 1 | E16: =COUNTIFS(Data!$T$2:$T$231,A16,Data!$B$2:$B$231,"Rejected") -> 3 | F16: =COUNTIFS(Data!$T$2:$T$231,A16,Data!$B$2:$B$231,"Cancelled") -> 4
A17: Mar 2026 | B17: =COUNTIF(Data!$T$2:$T$231,A17) -> 14 | C17: =COUNTIFS(Data!$T$2:$T$231,A17,Data!$B$2:$B$231,"Approved") -> 11 | D17: =COUNTIFS(Data!$T$2:$T$231,A17,Data!$B$2:$B$231,"Pending") -> 1 | E17: =COUNTIFS(Data!$T$2:$T$231,A17,Data!$B$2:$B$231,"Rejected") -> 1 | F17: =COUNTIFS(Data!$T$2:$T$231,A17,Data!$B$2:$B$231,"Cancelled") -> 1
A18: Apr 2026 | B18: =COUNTIF(Data!$T$2:$T$231,A18) -> 16 | C18: =COUNTIFS(Data!$T$2:$T$231,A18,Data!$B$2:$B$231,"Approved") -> 6 | D18: =COUNTIFS(Data!$T$2:$T$231,A18,Data!$B$2:$B$231,"Pending") -> 4 | E18: =COUNTIFS(Data!$T$2:$T$231,A18,Data!$B$2:$B$231,"Rejected") -> 3 | F18: =COUNTIFS(Data!$T$2:$T$231,A18,Data!$B$2:$B$231,"Cancelled") -> 3
A19: May 2026 | B19: =COUNTIF(Data!$T$2:$T$231,A19) -> 21 | C19: =COUNTIFS(Data!$T$2:$T$231,A19,Data!$B$2:$B$231,"Approved") -> 14 | D19: =COUNTIFS(Data!$T$2:$T$231,A19,Data!$B$2:$B$231,"Pending") -> 2 | E19: =COUNTIFS(Data!$T$2:$T$231,A19,Data!$B$2:$B$231,"Rejected") -> 1 | F19: =COUNTIFS(Data!$T$2:$T$231,A19,Data!$B$2:$B$231,"Cancelled") -> 4
A20: Jun 2026 | B20: =COUNTIF(Data!$T$2:$T$231,A20) -> 14 | C20: =COUNTIFS(Data!$T$2:$T$231,A20,Data!$B$2:$B$231,"Approved") -> 7 | D20: =COUNTIFS(Data!$T$2:$T$231,A20,Data!$B$2:$B$231,"Pending") -> 2 | E20: =COUNTIFS(Data!$T$2:$T$231,A20,Data!$B$2:$B$231,"Rejected") -> 3 | F20: =COUNTIFS(Data!$T$2:$T$231,A20,Data!$B$2:$B$231,"Cancelled") -> 2
A21: Jul 2026 | B21: =COUNTIF(Data!$T$2:$T$231,A21) -> 23 | C21: =COUNTIFS(Data!$T$2:$T$231,A21,Data!$B$2:$B$231,"Approved") -> 9 | D21: =COUNTIFS(Data!$T$2:$T$231,A21,Data!$B$2:$B$231,"Pending") -> 4 | E21: =COUNTIFS(Data!$T$2:$T$231,A21,Data!$B$2:$B$231,"Rejected") -> 3 | F21: =COUNTIFS(Data!$T$2:$T$231,A21,Data!$B$2:$B$231,"Cancelled") -> 7
A22: Aug 2026 | B22: =COUNTIF(Data!$T$2:$T$231,A22) -> 27 | C22: =COUNTIFS(Data!$T$2:$T$231,A22,Data!$B$2:$B$231,"Approved") -> 10 | D22: =COUNTIFS(Data!$T$2:$T$231,A22,Data!$B$2:$B$231,"Pending") -> 10 | E22: =COUNTIFS(Data!$T$2:$T$231,A22,Data!$B$2:$B$231,"Rejected") -> 5 | F22: =COUNTIFS(Data!$T$2:$T$231,A22,Data!$B$2:$B$231,"Cancelled") -> 2
A24: Trips by Purpose | D24: By Location | F24: By Van Type
A25: Purpose | B25: Count | D25: Location | E25: Count | F25: Van Type | G25: Count
A26: IT-Related | B26: =COUNTIF(Data!$J$2:$J$231,A26) -> 41 | D26: Manila | E26: =COUNTIF(Data!$G$2:$G$231,D26) -> 127 | F26: Pickup / Drop-Off | G26: =COUNTIF(Data!$L$2:$L$231,F26) -> 160
A27: HR/TA Related | B27: =COUNTIF(Data!$J$2:$J$231,A27) -> 47 | D27: Iloilo | E27: =COUNTIF(Data!$G$2:$G$231,D27) -> 103 | F27: Standby Van | G27: =COUNTIF(Data!$L$2:$L$231,F27) -> 70
A28: Travel-Related (Airport Transfers) | B28: =COUNTIF(Data!$J$2:$J$231,A28) -> 36
A29: Others | B29: =COUNTIF(Data!$J$2:$J$231,A29) -> 106
A32: By Requestor
A33: Requestor | B33: Total Requests | C33: Approved | D33: Approval Rate
A34: Cruz, Ivan | B34: =COUNTIF(Data!$F$2:$F$231,A34) -> 39 | C34: =COUNTIFS(Data!$F$2:$F$231,A34,Data!$B$2:$B$231,"Approved") -> 22 | D34: =IF(B34=0,0,C34/B34) -> 0.56410256
A35: Dizon, Marco | B35: =COUNTIF(Data!$F$2:$F$231,A35) -> 34 | C35: =COUNTIFS(Data!$F$2:$F$231,A35,Data!$B$2:$B$231,"Approved") -> 20 | D35: =IF(B35=0,0,C35/B35) -> 0.58823529
A36: Jimera, Arielle | B36: =COUNTIF(Data!$F$2:$F$231,A36) -> 38 | C36: =COUNTIFS(Data!$F$2:$F$231,A36,Data!$B$2:$B$231,"Approved") -> 19 | D36: =IF(B36=0,0,C36/B36) -> 0.5
A37: Mateo, Angel | B37: =COUNTIF(Data!$F$2:$F$231,A37) -> 32 | C37: =COUNTIFS(Data!$F$2:$F$231,A37,Data!$B$2:$B$231,"Approved") -> 18 | D37: =IF(B37=0,0,C37/B37) -> 0.5625
A38: Reyes, Kaye | B38: =COUNTIF(Data!$F$2:$F$231,A38) -> 49 | C38: =COUNTIFS(Data!$F$2:$F$231,A38,Data!$B$2:$B$231,"Approved") -> 25 | D38: =IF(B38=0,0,C38/B38) -> 0.51020408
A39: Salcedo, Liza | B39: =COUNTIF(Data!$F$2:$F$231,A39) -> 38 | C39: =COUNTIFS(Data!$F$2:$F$231,A39,Data!$B$2:$B$231,"Approved") -> 21 | D39: =IF(B39=0,0,C39/B39) -> 0.55263158
A42: Driver Utilization (assigned trips) | D42: Van Utilization
A43: Driver | B43: Trips Assigned | D43: Van | E43: Trips
A44: Ocampo, Dennis | B44: =COUNTIF(Data!$M$2:$M$231,A44) -> 34 | D44: VAN-001 | E44: =COUNTIF(Data!$N$2:$N$231,D44) -> 31
A45: Padilla, Marlon | B45: =COUNTIF(Data!$M$2:$M$231,A45) -> 39 | D45: VAN-002 | E45: =COUNTIF(Data!$N$2:$N$231,D45) -> 33
A46: Sarmiento, Joel | B46: =COUNTIF(Data!$M$2:$M$231,A46) -> 27 | D46: VAN-003 | E46: =COUNTIF(Data!$N$2:$N$231,D46) -> 32
...
